<?xml version="1.0" ?>
<!-- =================================================================================== -->
<!-- |    This document was autogenerated by xacro from resource/xacro/brunhilde.urdf.xacro | -->
<!-- |    EDITING THIS FILE BY HAND IS NOT RECOMMENDED                                 | -->
<!-- =================================================================================== -->
<robot name="brunhilde">
  <material name="petrol">
    <color rgba="0.0 0.59 1.0 1.0"/>
  </material>
  <link name="world"/>
  <joint name="fixed" type="fixed">
    <parent link="world"/>
    <child link="base_link"/>
  </joint>
  <!-- This file is based on: https://atlas.is.localnet/confluence/display/AMDW/Quadruped+URDF+Files -->
  <link name="base_link">
    <visual>
      <origin rpy="0 0 0" xyz="0 0 0"/>
      <geometry>
        <mesh filename="package://brunhilde_description/resource/xacro/meshes/solo_body.stl"/>
      </geometry>
      <material name="petrol"/>
    </visual>
    <collision>
      <origin rpy="0 0 0" xyz="0 0 0"/>
      <geometry>
        <mesh filename="package://brunhilde_description/resource/xacro/meshes/solo_body.stl"/>
      </geometry>
    </collision>
    <inertial>
      <origin rpy="0 0 0" xyz="0 0 0"/>
      <mass value="1.43315091"/>
      <inertia ixx="0.00578574" ixy="0.0" ixz="0.0" iyy="0.01938108" iyz="0.0" izz="0.02476124"/>
    </inertial>
  </link>
  <!-- Joint between the base and the ${prefix} upper leg -->
  <joint name="FL_HFE" type="revolute">
    <parent link="base_link"/>
    <child link="FL_UPPER_LEG"/>
    <limit effort="1000" lower="-10" upper="10" velocity="1000"/>
    <!-- joints rotates around the y-axis -->
    <axis xyz="0 1 0"/>
    <origin rpy="0 0 0" xyz="0.1946 0.1015 0"/>
    <!-- pybullet simulation parameters -->
    <dynamics damping="0.0" friction="0.0"/>
  </joint>
  <link name="FL_UPPER_LEG">
    <!-- Left upper leg inertia -->
    <inertial>
      <mass value="0.14737324"/>
      <origin rpy="0 0 0" xyz="0.00001530 0.01767640 -0.07838230"/>
      <inertia ixx="0.00041540" ixy="0.00000000" ixz="0.00000010" iyy="0.00041637" iyz="-0.00004589" izz="0.00002982"/>
    </inertial>
    <!-- UPPER LEG LINK VISUAL -->
    <visual>
      <origin rpy="0 0 0" xyz="0 0 0"/>
      <geometry>
        <mesh filename="package://brunhilde_description/resource/xacro/meshes/solo_upper_leg_left_side.stl"/>
      </geometry>
      <material name="petrol"/>
    </visual>
    <!-- UPPER LEG LINK COLLISION -->
    <collision>
      <origin rpy="0 0 0" xyz="0 0 0"/>
      <geometry>
        <mesh filename="package://brunhilde_description/resource/xacro/meshes/solo_upper_leg_left_side.stl"/>
      </geometry>
      <material name="petrol"/>
    </collision>
  </link>
  <!-- END UPPER LEG LINK -->
  <!-- KFE: Joint between the upper leg and the lower leg -->
  <joint name="FL_KFE" type="revolute">
    <parent link="FL_UPPER_LEG"/>
    <child link="FL_LOWER_LEG"/>
    <limit effort="1000" lower="-10" upper="10" velocity="1000"/>
    <!-- joints rotates around the y-axis -->
    <axis xyz="0 1 0"/>
    <origin rpy="0 0 0" xyz="0 0.037450000000000004 -0.16"/>
    <!-- pybullet simulation parameters -->
    <dynamics damping="0.0" friction="0.0"/>
  </joint>
  <link name="FL_LOWER_LEG">
    <!-- Left lower leg inertia -->
    <inertial>
      <mass value="0.02318294"/>
      <origin rpy="0 0 0" xyz="0.00000000 0.00776716 -0.07003876"/>
      <inertia ixx="0.00008508" ixy="0.00000000" ixz="0.00000000" iyy="0.00008580" iyz="-0.00000200" izz="0.00000139"/>
    </inertial>
    <!-- LOWER LEG LINK VISUAL -->
    <visual>
      <origin rpy="0 0 0" xyz="0 0 0"/>
      <geometry>
        <mesh filename="package://brunhilde_description/resource/xacro/meshes/solo_lower_leg_v2_left_side.stl"/>
      </geometry>
      <material name="petrol"/>
    </visual>
    <!-- LOWER LEG LINK COLLISION -->
    <collision>
      <origin rpy="0 0 0" xyz="0 0 0"/>
      <geometry>
        <mesh filename="package://brunhilde_description/resource/xacro/meshes/solo_lower_leg_v2_left_side.stl"/>
      </geometry>
      <material name="petrol"/>
    </collision>
  </link>
  <!-- END LOWER LEG LINK -->
  <!-- Joint between the lower leg and the ankle,
         this is only a dummy joint such that we
         can assign coordinate frames to foot-->
  <joint name="FL_ANKLE" type="fixed">
    <parent link="FL_LOWER_LEG"/>
    <child link="FL_FOOT"/>
    <origin rpy="0 0 0" xyz="0 0.009000000000000001 -0.16"/>
    <!-- Limits -->
    <limit effort="1000" lower="-10" upper="10" velocity="1000"/>
  </joint>
  <link name="FL_FOOT">
    <!-- FOOT INERTIAL -->
    <inertial>
      <origin rpy="0 0 0" xyz="0 0 0"/>
      <mass value="0.0"/>
      <inertia ixx="0.0" ixy="0.0" ixz="0.0" iyy="0.0" iyz="0.0" izz="0.0"/>
    </inertial>
  </link>
  <!-- END FOOT LINK -->
  <!-- Joint between the base and the ${prefix} upper leg -->
  <joint name="FR_HFE" type="revolute">
    <parent link="base_link"/>
    <child link="FR_UPPER_LEG"/>
    <limit effort="1000" lower="-10" upper="10" velocity="1000"/>
    <!-- joints rotates around the y-axis -->
    <axis xyz="0 1 0"/>
    <origin rpy="0 0 0" xyz="0.1946 -0.1015 0"/>
    <!-- pybullet simulation parameters -->
    <dynamics damping="0.0" friction="0.0"/>
  </joint>
  <link name="FR_UPPER_LEG">
    <!-- Right upper leg inertia -->
    <inertial>
      <mass value="0.14737324"/>
      <origin rpy="0 0 0" xyz="-0.00001530 -0.01767640 -0.07838230"/>
      <inertia ixx="0.00041540" ixy="0.00000000" ixz="-0.00000010" iyy="0.00041637" iyz="0.00004589" izz="0.00002982"/>
    </inertial>
    <!-- UPPER LEG LINK VISUAL -->
    <visual>
      <origin rpy="0 0 0" xyz="0 0 0"/>
      <geometry>
        <mesh filename="package://brunhilde_description/resource/xacro/meshes/solo_upper_leg_right_side.stl"/>
      </geometry>
      <material name="petrol"/>
    </visual>
    <!-- UPPER LEG LINK COLLISION -->
    <collision>
      <origin rpy="0 0 0" xyz="0 0 0"/>
      <geometry>
        <mesh filename="package://brunhilde_description/resource/xacro/meshes/solo_upper_leg_right_side.stl"/>
      </geometry>
      <material name="petrol"/>
    </collision>
  </link>
  <!-- END UPPER LEG LINK -->
  <!-- KFE: Joint between the upper leg and the lower leg -->
  <joint name="FR_KFE" type="revolute">
    <parent link="FR_UPPER_LEG"/>
    <child link="FR_LOWER_LEG"/>
    <limit effort="1000" lower="-10" upper="10" velocity="1000"/>
    <!-- joints rotates around the y-axis -->
    <axis xyz="0 1 0"/>
    <origin rpy="0 0 0" xyz="0 -0.037450000000000004 -0.16"/>
    <!-- pybullet simulation parameters -->
    <dynamics damping="0.0" friction="0.0"/>
  </joint>
  <link name="FR_LOWER_LEG">
    <!-- Right lower leg inertia -->
    <inertial>
      <mass value="0.02318294"/>
      <origin rpy="0 0 0" xyz="0.00000000 -0.00776716 -0.07003876"/>
      <inertia ixx="0.00008508" ixy="0.00000000" ixz="0.00000000" iyy="0.00008580" iyz="0.00000200" izz="0.00000139"/>
    </inertial>
    <!-- LOWER LEG LINK VISUAL -->
    <visual>
      <origin rpy="0 0 0" xyz="0 0 0"/>
      <geometry>
        <mesh filename="package://brunhilde_description/resource/xacro/meshes/solo_lower_leg_v2_right_side.stl"/>
      </geometry>
      <material name="petrol"/>
    </visual>
    <!-- LOWER LEG LINK COLLISION -->
    <collision>
      <origin rpy="0 0 0" xyz="0 0 0"/>
      <geometry>
        <mesh filename="package://brunhilde_description/resource/xacro/meshes/solo_lower_leg_v2_right_side.stl"/>
      </geometry>
      <material name="petrol"/>
    </collision>
  </link>
  <!-- END LOWER LEG LINK -->
  <!-- Joint between the lower leg and the ankle,
         this is only a dummy joint such that we
         can assign coordinate frames to foot-->
  <joint name="FR_ANKLE" type="fixed">
    <parent link="FR_LOWER_LEG"/>
    <child link="FR_FOOT"/>
    <origin rpy="0 0 0" xyz="0 -0.009000000000000001 -0.16"/>
    <!-- Limits -->
    <limit effort="1000" lower="-10" upper="10" velocity="1000"/>
  </joint>
  <link name="FR_FOOT">
    <!-- FOOT INERTIAL -->
    <inertial>
      <origin rpy="0 0 0" xyz="0 0 0"/>
      <mass value="0.0"/>
      <inertia ixx="0.0" ixy="0.0" ixz="0.0" iyy="0.0" iyz="0.0" izz="0.0"/>
    </inertial>
  </link>
  <!-- END FOOT LINK -->
  <!-- Joint between the base and the ${prefix} upper leg -->
  <joint name="HL_HFE" type="revolute">
    <parent link="base_link"/>
    <child link="HL_UPPER_LEG"/>
    <limit effort="1000" lower="-10" upper="10" velocity="1000"/>
    <!-- joints rotates around the y-axis -->
    <axis xyz="0 1 0"/>
    <origin rpy="0 0 0" xyz="-0.1946 0.1015 0"/>
    <!-- pybullet simulation parameters -->
    <dynamics damping="0.0" friction="0.0"/>
  </joint>
  <link name="HL_UPPER_LEG">
    <!-- Left upper leg inertia -->
    <inertial>
      <mass value="0.14737324"/>
      <origin rpy="0 0 0" xyz="0.00001530 0.01767640 -0.07838230"/>
      <inertia ixx="0.00041540" ixy="0.00000000" ixz="0.00000010" iyy="0.00041637" iyz="-0.00004589" izz="0.00002982"/>
    </inertial>
    <!-- UPPER LEG LINK VISUAL -->
    <visual>
      <origin rpy="0 0 0" xyz="0 0 0"/>
      <geometry>
        <mesh filename="package://brunhilde_description/resource/xacro/meshes/solo_upper_leg_left_side.stl"/>
      </geometry>
      <material name="petrol"/>
    </visual>
    <!-- UPPER LEG LINK COLLISION -->
    <collision>
      <origin rpy="0 0 0" xyz="0 0 0"/>
      <geometry>
        <mesh filename="package://brunhilde_description/resource/xacro/meshes/solo_upper_leg_left_side.stl"/>
      </geometry>
      <material name="petrol"/>
    </collision>
  </link>
  <!-- END UPPER LEG LINK -->
  <!-- KFE: Joint between the upper leg and the lower leg -->
  <joint name="HL_KFE" type="revolute">
    <parent link="HL_UPPER_LEG"/>
    <child link="HL_LOWER_LEG"/>
    <limit effort="1000" lower="-10" upper="10" velocity="1000"/>
    <!-- joints rotates around the y-axis -->
    <axis xyz="0 1 0"/>
    <origin rpy="0 0 0" xyz="0 0.037450000000000004 -0.16"/>
    <!-- pybullet simulation parameters -->
    <dynamics damping="0.0" friction="0.0"/>
  </joint>
  <link name="HL_LOWER_LEG">
    <!-- Left lower leg inertia -->
    <inertial>
      <mass value="0.02318294"/>
      <origin rpy="0 0 0" xyz="0.00000000 0.00776716 -0.07003876"/>
      <inertia ixx="0.00008508" ixy="0.00000000" ixz="0.00000000" iyy="0.00008580" iyz="-0.00000200" izz="0.00000139"/>
    </inertial>
    <!-- LOWER LEG LINK VISUAL -->
    <visual>
      <origin rpy="0 0 0" xyz="0 0 0"/>
      <geometry>
        <mesh filename="package://brunhilde_description/resource/xacro/meshes/solo_lower_leg_v2_left_side.stl"/>
      </geometry>
      <material name="petrol"/>
    </visual>
    <!-- LOWER LEG LINK COLLISION -->
    <collision>
      <origin rpy="0 0 0" xyz="0 0 0"/>
      <geometry>
        <mesh filename="package://brunhilde_description/resource/xacro/meshes/solo_lower_leg_v2_left_side.stl"/>
      </geometry>
      <material name="petrol"/>
    </collision>
  </link>
  <!-- END LOWER LEG LINK -->
  <!-- Joint between the lower leg and the ankle,
         this is only a dummy joint such that we
         can assign coordinate frames to foot-->
  <joint name="HL_ANKLE" type="fixed">
    <parent link="HL_LOWER_LEG"/>
    <child link="HL_FOOT"/>
    <origin rpy="0 0 0" xyz="0 0.009000000000000001 -0.16"/>
    <!-- Limits -->
    <limit effort="1000" lower="-10" upper="10" velocity="1000"/>
  </joint>
  <link name="HL_FOOT">
    <!-- FOOT INERTIAL -->
    <inertial>
      <origin rpy="0 0 0" xyz="0 0 0"/>
      <mass value="0.0"/>
      <inertia ixx="0.0" ixy="0.0" ixz="0.0" iyy="0.0" iyz="0.0" izz="0.0"/>
    </inertial>
  </link>
  <!-- END FOOT LINK -->
  <!-- Joint between the base and the ${prefix} upper leg -->
  <joint name="HR_HFE" type="revolute">
    <parent link="base_link"/>
    <child link="HR_UPPER_LEG"/>
    <limit effort="1000" lower="-10" upper="10" velocity="1000"/>
    <!-- joints rotates around the y-axis -->
    <axis xyz="0 1 0"/>
    <origin rpy="0 0 0" xyz="-0.1946 -0.1015 0"/>
    <!-- pybullet simulation parameters -->
    <dynamics damping="0.0" friction="0.0"/>
  </joint>
  <link name="HR_UPPER_LEG">
    <!-- Right upper leg inertia -->
    <inertial>
      <mass value="0.14737324"/>
      <origin rpy="0 0 0" xyz="-0.00001530 -0.01767640 -0.07838230"/>
      <inertia ixx="0.00041540" ixy="0.00000000" ixz="-0.00000010" iyy="0.00041637" iyz="0.00004589" izz="0.00002982"/>
    </inertial>
    <!-- UPPER LEG LINK VISUAL -->
    <visual>
      <origin rpy="0 0 0" xyz="0 0 0"/>
      <geometry>
        <mesh filename="package://brunhilde_description/resource/xacro/meshes/solo_upper_leg_right_side.stl"/>
      </geometry>
      <material name="petrol"/>
    </visual>
    <!-- UPPER LEG LINK COLLISION -->
    <collision>
      <origin rpy="0 0 0" xyz="0 0 0"/>
      <geometry>
        <mesh filename="package://brunhilde_description/resource/xacro/meshes/solo_upper_leg_right_side.stl"/>
      </geometry>
      <material name="petrol"/>
    </collision>
  </link>
  <!-- END UPPER LEG LINK -->
  <!-- KFE: Joint between the upper leg and the lower leg -->
  <joint name="HR_KFE" type="revolute">
    <parent link="HR_UPPER_LEG"/>
    <child link="HR_LOWER_LEG"/>
    <limit effort="1000" lower="-10" upper="10" velocity="1000"/>
    <!-- joints rotates around the y-axis -->
    <axis xyz="0 1 0"/>
    <origin rpy="0 0 0" xyz="0 -0.037450000000000004 -0.16"/>
    <!-- pybullet simulation parameters -->
    <dynamics damping="0.0" friction="0.0"/>
  </joint>
  <link name="HR_LOWER_LEG">
    <!-- Right lower leg inertia -->
    <inertial>
      <mass value="0.02318294"/>
      <origin rpy="0 0 0" xyz="0.00000000 -0.00776716 -0.07003876"/>
      <inertia ixx="0.00008508" ixy="0.00000000" ixz="0.00000000" iyy="0.00008580" iyz="0.00000200" izz="0.00000139"/>
    </inertial>
    <!-- LOWER LEG LINK VISUAL -->
    <visual>
      <origin rpy="0 0 0" xyz="0 0 0"/>
      <geometry>
        <mesh filename="package://brunhilde_description/resource/xacro/meshes/solo_lower_leg_v2_right_side.stl"/>
      </geometry>
      <material name="petrol"/>
    </visual>
    <!-- LOWER LEG LINK COLLISION -->
    <collision>
      <origin rpy="0 0 0" xyz="0 0 0"/>
      <geometry>
        <mesh filename="package://brunhilde_description/resource/xacro/meshes/solo_lower_leg_v2_right_side.stl"/>
      </geometry>
      <material name="petrol"/>
    </collision>
  </link>
  <!-- END LOWER LEG LINK -->
  <!-- Joint between the lower leg and the ankle,
         this is only a dummy joint such that we
         can assign coordinate frames to foot-->
  <joint name="HR_ANKLE" type="fixed">
    <parent link="HR_LOWER_LEG"/>
    <child link="HR_FOOT"/>
    <origin rpy="0 0 0" xyz="0 -0.009000000000000001 -0.16"/>
    <!-- Limits -->
    <limit effort="1000" lower="-10" upper="10" velocity="1000"/>
  </joint>
  <link name="HR_FOOT">
    <!-- FOOT INERTIAL -->
    <inertial>
      <origin rpy="0 0 0" xyz="0 0 0"/>
      <mass value="0.0"/>
      <inertia ixx="0.0" ixy="0.0" ixz="0.0" iyy="0.0" iyz="0.0" izz="0.0"/>
    </inertial>
  </link>
  <!-- END FOOT LINK -->
  <gazebo reference="base_link">
    <material>
      <ambient>1 0 0 1</ambient>
      <diffuse>1 0 0 1</diffuse>
      <specular>0.1 0.1 0.1 1</specular>
    </material>
  </gazebo>
  <gazebo reference="FL_FOOT">
    <material>
      <ambient>1 0 0 1</ambient>
      <diffuse>1 0 0 1</diffuse>
      <specular>0.1 0.1 0.1 1</specular>
    </material>
  </gazebo>
  <gazebo reference="FL_LOWER_LEG">
    <material>
      <ambient>1 0 0 1</ambient>
      <diffuse>1 0 0 1</diffuse>
      <specular>0.1 0.1 0.1 1</specular>
    </material>
  </gazebo>
  <gazebo reference="FL_UPPER_LEG">
    <material>
      <ambient>1 0 0 1</ambient>
      <diffuse>1 0 0 1</diffuse>
      <specular>0.1 0.1 0.1 1</specular>
    </material>
  </gazebo>
  <gazebo reference="FR_FOOT">
    <material>
      <ambient>1 0 0 1</ambient>
      <diffuse>1 0 0 1</diffuse>
      <specular>0.1 0.1 0.1 1</specular>
    </material>
  </gazebo>
  <gazebo reference="FR_LOWER_LEG">
    <material>
      <ambient>1 0 0 1</ambient>
      <diffuse>1 0 0 1</diffuse>
      <specular>0.1 0.1 0.1 1</specular>
    </material>
  </gazebo>
  <gazebo reference="FR_UPPER_LEG">
    <material>
      <ambient>1 0 0 1</ambient>
      <diffuse>1 0 0 1</diffuse>
      <specular>0.1 0.1 0.1 1</specular>
    </material>
  </gazebo>
  <gazebo reference="HL_FOOT">
    <material>
      <ambient>1 0 0 1</ambient>
      <diffuse>1 0 0 1</diffuse>
      <specular>0.1 0.1 0.1 1</specular>
    </material>
  </gazebo>
  <gazebo reference="HL_LOWER_LEG">
    <material>
      <ambient>1 0 0 1</ambient>
      <diffuse>1 0 0 1</diffuse>
      <specular>0.1 0.1 0.1 1</specular>
    </material>
  </gazebo>
  <gazebo reference="HL_UPPER_LEG">
    <material>
      <ambient>1 0 0 1</ambient>
      <diffuse>1 0 0 1</diffuse>
      <specular>0.1 0.1 0.1 1</specular>
    </material>
  </gazebo>
  <gazebo reference="HR_FOOT">
    <material>
      <ambient>1 0 0 1</ambient>
      <diffuse>1 0 0 1</diffuse>
      <specular>0.1 0.1 0.1 1</specular>
    </material>
  </gazebo>
  <gazebo reference="HR_LOWER_LEG">
    <material>
      <ambient>1 0 0 1</ambient>
      <diffuse>1 0 0 1</diffuse>
      <specular>0.1 0.1 0.1 1</specular>
    </material>
  </gazebo>
  <gazebo reference="HR_UPPER_LEG">
    <material>
      <ambient>1 0 0 1</ambient>
      <diffuse>1 0 0 1</diffuse>
      <specular>0.1 0.1 0.1 1</specular>
    </material>
  </gazebo>
  <!--<plugin filename="gz-sim-joint-state-publisher-system"
          name="gz::sim::systems::JointStatePublisher">
    <joint_name>FL_HFE</joint_name>
    <joint_name>FL_KFE</joint_name>
    <joint_name>FR_HFE</joint_name>
    <joint_name>FR_KFE</joint_name>
    <joint_name>HL_HFE</joint_name>
    <joint_name>HL_KFE</joint_name>
    <joint_name>HR_HFE</joint_name>
    <joint_name>HR_KFE</joint_name>
  </plugin>-->
  <ros2_control name="brunhilde" type="system">
    <hardware>
      <plugin>gz_ros2_control/GazeboSimSystem</plugin>
      <!--<xacro:if value="${use_mock_hardware}">
        <plugin>mock_components/GenericSystem</plugin>
        <param name="calculate_dynamics">true</param>
				<param name="state_following_offset">0.0</param>
			</xacro:if>-->
    </hardware>
    <joint name="FL_HFE">
      <command_interface name="position">
        <param name="min">-0.5</param>
        <param name="max">0.5</param>
      </command_interface>
      <command_interface name="velocity">
        <param name="min">-1</param>
        <param name="max">1</param>
      </command_interface>
      <command_interface name="effort">
        <param name="min">-1</param>
        <param name="max">1</param>
      </command_interface>
      <command_interface name="gain_kp">
        <param name="min">-1000</param>
        <param name="max">1000</param>
      </command_interface>
      <command_interface name="gain_kd">
        <param name="min">-1000</param>
        <param name="max">1000</param>
      </command_interface>
      <state_interface name="position"/>
      <state_interface name="velocity"/>
      <state_interface name="effort"/>
      <state_interface name="gain_kp"/>
      <state_interface name="gain_kd"/>
      <param name="motor_number">0</param>
      <param name="gear_ratio">9.</param>
      <param name="motor_constant">0.025</param>
      <param name="max_current">12.</param>
      <param name="max_joint_velocity">80.</param>
      <param name="safety_damping">0.5</param>
      <param name="motor_reversed_polarity">true</param>
      <param name="position_offset">0.238</param>
    </joint>
    <joint name="FL_KFE">
      <command_interface name="position">
        <param name="min">-0.5</param>
        <param name="max">0.5</param>
      </command_interface>
      <command_interface name="velocity">
        <param name="min">-1</param>
        <param name="max">1</param>
      </command_interface>
      <command_interface name="effort">
        <param name="min">-1</param>
        <param name="max">1</param>
      </command_interface>
      <command_interface name="gain_kp">
        <param name="min">-1000</param>
        <param name="max">1000</param>
      </command_interface>
      <command_interface name="gain_kd">
        <param name="min">-1000</param>
        <param name="max">1000</param>
      </command_interface>
      <state_interface name="position"/>
      <state_interface name="velocity"/>
      <state_interface name="effort"/>
      <state_interface name="gain_kp"/>
      <state_interface name="gain_kd"/>
      <param name="motor_number">0</param>
      <param name="gear_ratio">9.</param>
      <param name="motor_constant">0.025</param>
      <param name="max_current">12.</param>
      <param name="max_joint_velocity">80.</param>
      <param name="safety_damping">0.5</param>
      <param name="motor_reversed_polarity">true</param>
      <param name="position_offset">0.238</param>
    </joint>
    <joint name="FR_HFE">
      <command_interface name="position">
        <param name="min">-0.5</param>
        <param name="max">0.5</param>
      </command_interface>
      <command_interface name="velocity">
        <param name="min">-1</param>
        <param name="max">1</param>
      </command_interface>
      <command_interface name="effort">
        <param name="min">-1</param>
        <param name="max">1</param>
      </command_interface>
      <command_interface name="gain_kp">
        <param name="min">-1000</param>
        <param name="max">1000</param>
      </command_interface>
      <command_interface name="gain_kd">
        <param name="min">-1000</param>
        <param name="max">1000</param>
      </command_interface>
      <state_interface name="position"/>
      <state_interface name="velocity"/>
      <state_interface name="effort"/>
      <state_interface name="gain_kp"/>
      <state_interface name="gain_kd"/>
      <param name="motor_number">0</param>
      <param name="gear_ratio">9.</param>
      <param name="motor_constant">0.025</param>
      <param name="max_current">12.</param>
      <param name="max_joint_velocity">80.</param>
      <param name="safety_damping">0.5</param>
      <param name="motor_reversed_polarity">true</param>
      <param name="position_offset">0.238</param>
    </joint>
    <joint name="FR_KFE">
      <command_interface name="position">
        <param name="min">-0.5</param>
        <param name="max">0.5</param>
      </command_interface>
      <command_interface name="velocity">
        <param name="min">-1</param>
        <param name="max">1</param>
      </command_interface>
      <command_interface name="effort">
        <param name="min">-1</param>
        <param name="max">1</param>
      </command_interface>
      <command_interface name="gain_kp">
        <param name="min">-1000</param>
        <param name="max">1000</param>
      </command_interface>
      <command_interface name="gain_kd">
        <param name="min">-1000</param>
        <param name="max">1000</param>
      </command_interface>
      <state_interface name="position"/>
      <state_interface name="velocity"/>
      <state_interface name="effort"/>
      <state_interface name="gain_kp"/>
      <state_interface name="gain_kd"/>
      <param name="motor_number">0</param>
      <param name="gear_ratio">9.</param>
      <param name="motor_constant">0.025</param>
      <param name="max_current">12.</param>
      <param name="max_joint_velocity">80.</param>
      <param name="safety_damping">0.5</param>
      <param name="motor_reversed_polarity">true</param>
      <param name="position_offset">0.238</param>
    </joint>
    <joint name="HL_HFE">
      <command_interface name="position">
        <param name="min">-0.5</param>
        <param name="max">0.5</param>
      </command_interface>
      <command_interface name="velocity">
        <param name="min">-1</param>
        <param name="max">1</param>
      </command_interface>
      <command_interface name="effort">
        <param name="min">-1</param>
        <param name="max">1</param>
      </command_interface>
      <command_interface name="gain_kp">
        <param name="min">-1000</param>
        <param name="max">1000</param>
      </command_interface>
      <command_interface name="gain_kd">
        <param name="min">-1000</param>
        <param name="max">1000</param>
      </command_interface>
      <state_interface name="position"/>
      <state_interface name="velocity"/>
      <state_interface name="effort"/>
      <state_interface name="gain_kp"/>
      <state_interface name="gain_kd"/>
      <param name="motor_number">0</param>
      <param name="gear_ratio">9.</param>
      <param name="motor_constant">0.025</param>
      <param name="max_current">12.</param>
      <param name="max_joint_velocity">80.</param>
      <param name="safety_damping">0.5</param>
      <param name="motor_reversed_polarity">true</param>
      <param name="position_offset">0.238</param>
    </joint>
    <joint name="HL_KFE">
      <command_interface name="position">
        <param name="min">-0.5</param>
        <param name="max">0.5</param>
      </command_interface>
      <command_interface name="velocity">
        <param name="min">-1</param>
        <param name="max">1</param>
      </command_interface>
      <command_interface name="effort">
        <param name="min">-1</param>
        <param name="max">1</param>
      </command_interface>
      <command_interface name="gain_kp">
        <param name="min">-1000</param>
        <param name="max">1000</param>
      </command_interface>
      <command_interface name="gain_kd">
        <param name="min">-1000</param>
        <param name="max">1000</param>
      </command_interface>
      <state_interface name="position"/>
      <state_interface name="velocity"/>
      <state_interface name="effort"/>
      <state_interface name="gain_kp"/>
      <state_interface name="gain_kd"/>
      <param name="motor_number">0</param>
      <param name="gear_ratio">9.</param>
      <param name="motor_constant">0.025</param>
      <param name="max_current">12.</param>
      <param name="max_joint_velocity">80.</param>
      <param name="safety_damping">0.5</param>
      <param name="motor_reversed_polarity">true</param>
      <param name="position_offset">0.238</param>
    </joint>
    <joint name="HR_HFE">
      <command_interface name="position">
        <param name="min">-0.5</param>
        <param name="max">0.5</param>
      </command_interface>
      <command_interface name="velocity">
        <param name="min">-1</param>
        <param name="max">1</param>
      </command_interface>
      <command_interface name="effort">
        <param name="min">-1</param>
        <param name="max">1</param>
      </command_interface>
      <command_interface name="gain_kp">
        <param name="min">-1000</param>
        <param name="max">1000</param>
      </command_interface>
      <command_interface name="gain_kd">
        <param name="min">-1000</param>
        <param name="max">1000</param>
      </command_interface>
      <state_interface name="position"/>
      <state_interface name="velocity"/>
      <state_interface name="effort"/>
      <state_interface name="gain_kp"/>
      <state_interface name="gain_kd"/>
      <param name="motor_number">0</param>
      <param name="gear_ratio">9.</param>
      <param name="motor_constant">0.025</param>
      <param name="max_current">12.</param>
      <param name="max_joint_velocity">80.</param>
      <param name="safety_damping">0.5</param>
      <param name="motor_reversed_polarity">true</param>
      <param name="position_offset">0.238</param>
    </joint>
    <joint name="HR_KFE">
      <command_interface name="position">
        <param name="min">-0.5</param>
        <param name="max">0.5</param>
      </command_interface>
      <command_interface name="velocity">
        <param name="min">-1</param>
        <param name="max">1</param>
      </command_interface>
      <command_interface name="effort">
        <param name="min">-1</param>
        <param name="max">1</param>
      </command_interface>
      <command_interface name="gain_kp">
        <param name="min">-1000</param>
        <param name="max">1000</param>
      </command_interface>
      <command_interface name="gain_kd">
        <param name="min">-1000</param>
        <param name="max">1000</param>
      </command_interface>
      <state_interface name="position"/>
      <state_interface name="velocity"/>
      <state_interface name="effort"/>
      <state_interface name="gain_kp"/>
      <state_interface name="gain_kd"/>
      <param name="motor_number">0</param>
      <param name="gear_ratio">9.</param>
      <param name="motor_constant">0.025</param>
      <param name="max_current">12.</param>
      <param name="max_joint_velocity">80.</param>
      <param name="safety_damping">0.5</param>
      <param name="motor_reversed_polarity">true</param>
      <param name="position_offset">0.238</param>
    </joint>
  </ros2_control>
  <gazebo>
    <plugin filename="libgz_ros2_control-system.so" name="gz_ros2_control::GazeboSimROS2ControlPlugin">
      <robot_param>robot_description</robot_param>
      <robot_param_node>robot_state_publisher</robot_param_node>
      <parameters>/home/brunhilde_ws/install/brunhilde_control/share/brunhilde_control/config/ros2_control.yaml</parameters>
    </plugin>
  </gazebo>
</robot>
