<?xml version="1.0"?>

<robot xmlns:xacro="http://playerstage.sourceforge.net/gazebo/xmlschema/#interface" name="solo">

  <!-- See https://github.com/open-dynamic-robot-initiative/open_robot_actuator_hardware/blob/master/mechanics/quadruped_robot_12dof_v1/README.md#quadruped-robot-12dof-v1 -->
  <!-- These are absoulte distance value, the sign are decided below -->
  <xacro:property name="base_2_HAA_x" value="${214.10 * 0.001}" />
  <xacro:property name="base_2_HAA_y" value="${87.50 * 0.001}" />

  <xacro:property name="HAA_2_HFE_y" value="${14.0 * 0.001}" />
  <xacro:property name="HAA_2_HFE_x" value="${19.5 * 0.001}" />

  <xacro:property name="base_2_HFE_x" value="${194.60 * 0.001}" />
  <xacro:property name="base_2_HFE_y" value="${101.50 * 0.001}" />

  <xacro:property name="HFE_2_KFE_y" value="${37.45 * 0.001}" />
  <xacro:property name="HFE_2_KFE_z" value="${160.00 * 0.001}" />

  <xacro:property name="KFE_2_FOOT_y" value="${9.0 * 0.001}" />
  <xacro:property name="KFE_2_FOOT_z" value="${160.00 * 0.001}" />

  <!-- Macro defining solo leg. -->
  <xacro:macro name="leg" params="prefix is_front is_right mesh_path
                                  mesh_ext color_name">

    <!-- Joint between the base and the ${prefix} upper leg -->
    <joint name="${prefix}_HFE" type="revolute">
      <parent link="body_frame"/>
      <child link="${prefix}_UPPER_LEG"/>
      <limit effort="1000" lower="-10" upper="10" velocity="1000"/>
      <!-- joints rotates around the y-axis -->
      <axis xyz="0 1 0"/>
      <!-- placement of the joint -->
      <xacro:if value="${is_front}">
        <xacro:unless value="${is_right}">
          <origin xyz="${base_2_HFE_x} ${base_2_HFE_y} 0" rpy="0 0 0" />
        </xacro:unless>
        <xacro:if value="${is_right}">
          <origin xyz="${base_2_HFE_x} ${-base_2_HFE_y} 0" rpy="0 0 0" />
        </xacro:if>
      </xacro:if>
      <xacro:unless value="${is_front}">
        <xacro:unless value="${is_right}">
          <origin xyz="${-base_2_HFE_x} ${base_2_HFE_y} 0" rpy="0 0 0" />
        </xacro:unless>
        <xacro:if value="${is_right}">
          <origin xyz="${-base_2_HFE_x} ${-base_2_HFE_y} 0" rpy="0 0 0" />
        </xacro:if>
      </xacro:unless>
      <!-- pybullet simulation parameters -->
      <dynamics damping="0.0" friction="0.0"/>
    </joint>

    <link name="${prefix}_UPPER_LEG">
      <!-- UPPER LEG LINK INERTIAL -->
      <xacro:unless value="${is_right}">
        <!-- Left upper leg inertia -->
        <inertial>
        <mass value="0.14737324"/>
        <origin xyz="0.00001530 0.01767640 -0.07838230" rpy="0 0 0" />
        <inertia ixx="0.00041540"  ixy="0.00000000" ixz="0.00000010"
                                   iyy="0.00041637" iyz="-0.00004589"
                                                    izz="0.00002982"/>
        </inertial>
      </xacro:unless>
      <xacro:if value="${is_right}">
        <!-- Right upper leg inertia -->
        <inertial>
        <mass value="0.14737324"/>
        <origin xyz="-0.00001530 -0.01767640 -0.07838230" rpy="0 0 0" />
        <inertia ixx="0.00041540"  ixy="0.00000000" ixz="-0.00000010"
                                   iyy="0.00041637" iyz="0.00004589"
                                                    izz="0.00002982"/>
        </inertial>
      </xacro:if>
      <!-- UPPER LEG LINK VISUAL -->
      <visual>
        <origin xyz="0 0 0" rpy="0 0 0" />
        <geometry>
          <xacro:unless value="${is_right}">
            <mesh filename="${mesh_path}solo_upper_leg_left_side.${mesh_ext}"/>
          </xacro:unless>
          <xacro:if value="${is_right}">
            <mesh filename="${mesh_path}solo_upper_leg_right_side.${mesh_ext}"/>
          </xacro:if>
        </geometry>
        <material name="${color_name}"/>
      </visual>
      <!-- UPPER LEG LINK COLLISION -->
      <collision>
        <origin xyz="0 0 0" rpy="0 0 0" />
        <geometry>
          <xacro:unless value="${is_right}">
            <mesh filename="${mesh_path}solo_upper_leg_left_side.${mesh_ext}"/>
          </xacro:unless>
          <xacro:if value="${is_right}">
            <mesh filename="${mesh_path}solo_upper_leg_right_side.${mesh_ext}"/>
          </xacro:if>
        </geometry>
        <material name="${color_name}"/>
      </collision>
    </link>
    <!-- END UPPER LEG LINK -->

    <!-- KFE: Joint between the upper leg and the lower leg -->
    <joint name="${prefix}_KFE" type="revolute">
      <parent link="${prefix}_UPPER_LEG"/>
      <child link="${prefix}_LOWER_LEG"/>
      <limit effort="1000" lower="-10" upper="10" velocity="1000"/>
      <!-- joints rotates around the y-axis -->
      <axis xyz="0 1 0"/>
      <!-- placement of the joint -->
      <xacro:if value="${is_front}">
        <xacro:unless value="${is_right}">
          <origin xyz="0 ${HFE_2_KFE_y} ${-HFE_2_KFE_z}" rpy="0 0 0" />
        </xacro:unless>
        <xacro:if value="${is_right}">
          <origin xyz="0 ${-HFE_2_KFE_y} ${-HFE_2_KFE_z}" rpy="0 0 0" />
        </xacro:if>
      </xacro:if>
      <xacro:unless value="${is_front}">
        <xacro:unless value="${is_right}">
          <origin xyz="0 ${HFE_2_KFE_y} ${-HFE_2_KFE_z}" rpy="0 0 0" />
        </xacro:unless>
        <xacro:if value="${is_right}">
          <origin xyz="0 ${-HFE_2_KFE_y} ${-HFE_2_KFE_z}" rpy="0 0 0" />
        </xacro:if>
      </xacro:unless>
      <!-- pybullet simulation parameters -->
      <dynamics damping="0.0" friction="0.0"/>
    </joint>

    <link name="${prefix}_LOWER_LEG">
      <!-- LOWER LEG LINK INERTIAL -->
      <xacro:unless value="${is_right}">
        <!-- Left lower leg inertia -->
        <inertial>
        <mass value="0.02318294"/>
        <origin xyz="0.00000000 0.00776716 -0.07003876" rpy="0 0 0" />
        <inertia ixx="0.00008508" ixy="0.00000000"  ixz="0.00000000"
                                  iyy="0.00008580"  iyz="-0.00000200"
                                                    izz="0.00000139"/>
        </inertial>
      </xacro:unless>
      <xacro:if value="${is_right}">
        <!-- Right lower leg inertia -->
        <inertial>
        <mass value="0.02318294"/>
        <origin xyz="0.00000000 -0.00776716 -0.07003876" rpy="0 0 0" />
        <inertia ixx="0.00008508" ixy="0.00000000"  ixz="0.00000000"
                                  iyy="0.00008580"  iyz="0.00000200"
                                                    izz="0.00000139"/>
        </inertial>
      </xacro:if>
      <!-- LOWER LEG LINK VISUAL -->
      <visual>
        <origin xyz="0 0 0" rpy="0 0 0" />
        <geometry>
          <xacro:unless value="${is_right}">
            <mesh filename="${mesh_path}solo_lower_leg_v2_left_side.${mesh_ext}"/>
          </xacro:unless>
          <xacro:if value="${is_right}">
            <mesh filename="${mesh_path}solo_lower_leg_v2_right_side.${mesh_ext}"/>
          </xacro:if>
        </geometry>
        <material name="${color_name}"/>
      </visual>
      <!-- LOWER LEG LINK COLLISION -->
      <collision>
        <origin xyz="0 0 0" rpy="0 0 0" />
        <geometry>
          <xacro:unless value="${is_right}">
            <mesh filename="${mesh_path}solo_lower_leg_v2_left_side.${mesh_ext}"/>
          </xacro:unless>
          <xacro:if value="${is_right}">
            <mesh filename="${mesh_path}solo_lower_leg_v2_right_side.${mesh_ext}"/>
          </xacro:if>
        </geometry>
        <material name="${color_name}"/>
      </collision>
    </link>
    <!-- END LOWER LEG LINK -->

    <!-- Joint between the lower leg and the ankle,
         this is only a dummy joint such that we
         can assign coordinate frames to foot-->
    <joint name="${prefix}_ANKLE" type="fixed">
      <parent link="${prefix}_LOWER_LEG"/>
      <child link="${prefix}_FOOT"/>
      <!-- Joint placement -->
      <xacro:unless value="${is_right}">
        <origin xyz="0 ${KFE_2_FOOT_y} ${-KFE_2_FOOT_z}" rpy="0 0 0" />
      </xacro:unless>
      <xacro:if value="${is_right}">
        <origin xyz="0 ${-KFE_2_FOOT_y} ${-KFE_2_FOOT_z}" rpy="0 0 0" />
      </xacro:if>
      <!-- Limits -->
      <limit effort="1000" lower="-10" upper="10" velocity="1000"/>
    </joint>

    <link name="${prefix}_FOOT">
      <!-- FOOT INERTIAL -->
      <inertial>
        <origin xyz="0 0 0" rpy="0 0 0" />
        <mass value="0.0"/>
        <inertia ixx="0.0" ixy="0.0" ixz="0.0"
                           iyy="0.0" iyz="0.0"
                                     izz="0.0"/>
      </inertial>
    </link> <!-- END FOOT LINK -->

  </xacro:macro>
</robot>
