<?xml version="1.0"?>
<robot xmlns:xacro="http://www.ros.org/wiki/xacro"  name="robot">

    <!-- This is an example of a URDF. -->
    <!-- As we move through the file, new things to note will be pointed out. -->
    <!-- It's not meant an example of GOOD design, but an example of some of the various features of URDF/xacro. -->

    <link name="base_link">
    </link>
  
    <joint name="base_joint" type="fixed">
      <origin xyz="0 0 0" rpy="0 0 0" />
      <parent link="base_link"/>
      <child link="body_frame"/>
    </joint>



    <xacro:property name="joint_angle" value="${pi/4}" />
    <xacro:property name="knee_angle" value="joint_angle*2" />


    <!-- body_frame is a large rectangular plate. Some things to note: -->
    <!-- - We set the visual origin Z to half the box height, so that the link origin sits at the bottom of the box -->
    <!-- - We set the collision to be identical to the visual -->
    <!-- - We specified the colour manually (but still need to enter a name) -->
    <!-- - We specified all the inertial parameters manually -->
    <link name="body_frame">
        <visual>
            <geometry>
                <mesh filename="package://watschel_description/meshes/3d_modelle/Hip.stl" scale="0.01 0.01 0.01"/>
            </geometry>
            <material name="green">
                <color rgba="0.2 1 0.2 1"/>
            </material>
        </visual>
        <collision>
            <geometry>
                <box size="1.2 0.3 0.1">
                </box>
                <origin xyz="0.0 4.0 0.0"/>
            </geometry>
        </collision>
        <inertial>
            <origin xyz="0 0.28 0.09" rpy="0 0 0"/>
            <mass value="172" />
            <inertia ixx="65.06899629082241" ixy="0.0" ixz="0.0" iyy="188.99729683407716" iyz="0.0" izz="242.36785108586454" />
        </inertial>
    </link>

    <joint name="left_hip_joint" type="revolute">
        <origin xyz="-0.36 0.24 0.05" rpy="0 0 0"/>
        <parent link="body_frame"/>
        <child link="leg_upper_left"/>
        <axis xyz="-1 0 0"/>
        <limit lower="${-pi/4}" upper="${pi/4}" velocity="100" effort="100"/> 
    </joint>

    <link name="leg_upper_left">
        <visual>
            <geometry>
                <mesh filename="package://watschel_description/meshes/3d_modelle/Left_leg/Top_leg_front.stl" scale="0.01 0.01 0.01"/>
            </geometry>
            <material name="green">
                <color rgba="0.2 1 0.2 1"/>
            </material>
        </visual>
        <inertial>
            <mass value="10"/>
            <inertia ixx="42.70110889206565" ixy="0.0" ixz="0.0" iyy="54.35021715917743" iyz="0.0" izz="15.553565591531272"/>
        </inertial>
    </link>

    <joint name="support_upper_left_joint" type="fixed">
        <origin xyz="-0.36 0.5 0.05" rpy="0 0 0"/>
        <parent link="body_frame"/>
        <child link="support_upper_left"/>
        <axis xyz="-1 0 0"/>
        <limit lower="${-pi/4}" upper="${pi/4}" velocity="100" effort="100"/> 
        <mimic joint="left_hip_joint" multiplier="1"/> 
    </joint>

    <link name="support_upper_left">
        <visual>
            <geometry>
                <mesh filename="package://watschel_description/meshes/3d_modelle/Left_leg/Top_leg_back.stl" scale="0.01 0.01 0.01"/>
            </geometry>
            <material name="green">
                <color rgba="0.2 1 0.2 1"/>
            </material>
        </visual>
        <inertial>
            <mass value="10"/>
            <inertia ixx="0.4" ixy="0.0" ixz="0.0" iyy="0.4" iyz="0.0" izz="0.2"/>
        </inertial>
    </link>

    <joint name="support_upper_right_joint" type="fixed">

        <origin xyz="0.36 0.5 0.05" rpy="0 0 0"/>
        <parent link="body_frame"/>
        <child link="support_upper_right"/>
        <axis xyz="-1 0 0"/>
        <limit lower="${-pi/4}" upper="${pi/4}" velocity="100" effort="100"/> 
        <mimic joint="left_hip_joint" multiplier="1"/> 
    </joint>

    <link name="support_upper_right">
        <visual>
            <geometry>
                <mesh filename="package://watschel_description/meshes/3d_modelle/Right_leg/Top_leg_back.stl" scale="0.01 0.01 0.01"/>
            </geometry>
            <material name="green">
                <color rgba="0.2 1 0.2 1"/>
            </material>
        </visual>
        <inertial>
            <mass value="10"/>
            <inertia ixx="0.4" ixy="0.0" ixz="0.0" iyy="0.4" iyz="0.0" izz="0.2"/>
        </inertial>
    </link>

    <joint name="right_hip_joint" type="revolute">
        <origin xyz="0.36 0.24 0.05" rpy="0 0 0"/>
        <parent link="body_frame"/>
        <child link="leg_upper_right"/>
        <axis xyz="-1 0 0"/>
        <limit lower="${-pi/4}" upper="${pi/4}" velocity="100" effort="100"/> 
    </joint>

    <link name="leg_upper_right">
        <visual>
            <geometry>
                <mesh filename="package://watschel_description/meshes/3d_modelle/Right_leg/Top_leg_front.stl" scale="0.01 0.01 0.01"/>
                <box size="0.6 0.1 0.2"/>
            </geometry>
            <material name="green">
                <color rgba="0.2 1 0.2 1"/>
            </material>
        </visual>
        <inertial>
            <mass value="10"/>
            <inertia ixx="42.70110889206565" ixy="0.0" ixz="0.0" iyy="54.35021715917743" iyz="0.0" izz="15.553565591531272"/>
        </inertial>
    </link>

    <joint name="knee_left_joint" type="revolute">
        <origin xyz="0 0 -0.65" rpy="0 0 0"/>
        <parent link="leg_upper_left"/>
        <child link="knee_left"/>
        <axis xyz="-1 0 0"/>
        <limit lower="-1" upper="1" effort="0.0" velocity="0.0"/>
        <mimic joint="left_hip_joint" multiplier="-1"/>
    </joint>

    <link name="knee_left">
        <visual>
            <geometry>
                <mesh filename="package://watschel_description/meshes/3d_modelle/Left_leg/Knee.stl" scale="0.01 0.01 0.01"/> 
            </geometry>
            <material name="green">
                <color rgba="0.0 1 0.2 1"/>
            </material>
        </visual>
        <inertial>
            <mass value="20"/>
            <inertia ixx="50.868164916992344" ixy="0.0" ixz="0.0" iyy="22.91604242324853" iyz="0.0" izz="63.92287750625619"/>
        </inertial>
    </link>

    <joint name="knee_right_joint" type="fixed">
        <origin xyz="0 0 -0.65" rpy="0 0 0"/>
        <parent link="leg_upper_right"/>
        <child link="knee_right"/>
        <axis xyz="-1 0 0"/>
        <mimic joint="right_hip_joint" multiplier="-1"/>
    </joint>

    <link name="knee_right">
        <visual>
            <geometry>
                <mesh filename="package://watschel_description/meshes/3d_modelle/Left_leg/Knee.stl" scale="0.01 0.01 0.01"/> 
            </geometry>
            <material name="green">
                <color rgba="0.0 1 0.2 1"/>
            </material>
        </visual>
        <inertial>
            <mass value="20"/>
            <inertia ixx="50.868164916992344" ixy="0.0" ixz="0.0" iyy="22.91604242324853" iyz="0.0" izz="63.92287750625619"/>
        </inertial>
    </link>

    <joint name="lower_leg_right_joint" type="revolute">
        <origin xyz="0 0 0" rpy="0 0 0"/>
        <parent link="knee_right"/>
        <child link="leg_lower_right"/>
        <axis xyz="-1 0 0"/>
        <limit lower="${-pi/4}" upper="${pi/4}" velocity="100" effort="100"/> 
    </joint>

    <link name="leg_lower_right">
        <visual>
            <geometry>
                <mesh filename="package://watschel_description/meshes/3d_modelle/Right_leg/Low_leg_front.stl" scale="0.01 0.01 0.01"/> 
            </geometry>
            <material name="green">
                <color rgba="0.0 1 0.2 1"/>
            </material>
        </visual>
        <inertial>
            <mass value="10"/>
            <inertia ixx="44.06199538400554" ixy="0.0" ixz="0.0" iyy="60.37315620362157" iyz="0.0" izz="20.349008232508035"/>
        </inertial>
    </link>

    <joint name="lower_leg_left_joint" type="revolute">
        <origin xyz="0 0 0" rpy="0 0 0"/>
        <parent link="knee_left"/>
        <child link="leg_lower_left"/>
        <axis xyz="-1 0 0"/>
        <limit lower="${-pi/4}" upper="${pi/4}" velocity="100" effort="100"/> 
    </joint>

    <link name="leg_lower_left">
        <visual>
            <geometry>
                <mesh filename="package://watschel_description/meshes/3d_modelle/Left_leg/Low_leg_front.stl" scale="0.01 0.01 0.01"/> 
            </geometry>
            <material name="green">
                <color rgba="0.0 1 0.2 1"/>
            </material>
        </visual>
        <inertial>
            <mass value="10"/>
            <inertia ixx="44.06199538400554" ixy="0.0" ixz="0.0" iyy="60.37315620362157" iyz="0.0" izz="20.349008232508035"/>
        </inertial>
    </link>

    <joint name="foot_left_joint" type="fixed">
        <origin xyz="0 0.05 -0.65"/>
        <parent link="leg_lower_left"/>
        <child link="foot_left"/>
        <axis xyz="-1 0 0"/>
        <mimic  joint="lower_leg_left_joint" multiplier="-1" />

    </joint>

    <joint name="support_lower_right_joint" type="fixed">

        <origin xyz="-0.15 0.15 0" rpy="0 0 0"/>
        <parent link="knee_right"/>
        <child link="support_lower_right"/>
        <axis xyz="-1 0 0"/>
        <limit lower="${-pi/4}" upper="${pi/4}" velocity="100" effort="100"/> 
        <mimic joint="lower_leg_right_joint" multiplier="1"/> 
    </joint>

    <link name="support_lower_right">
        <visual>
            <geometry>
                <mesh filename="package://watschel_description/meshes/3d_modelle/Right_leg/Low_leg_back.stl" scale="0.01 0.01 0.01"/>
            </geometry>
            <material name="green">
                <color rgba="0.2 1 0.2 1"/>
            </material>
        </visual>
        <inertial>
            <mass value="10"/>
            <inertia ixx="0.4" ixy="0.0" ixz="0.0" iyy="0.4" iyz="0.0" izz="0.2"/>
        </inertial>
    </link>

    <joint name="support_lower_left_joint" type="fixed">

        <origin xyz="0 0.15 0" rpy="0 0 0"/>
        <parent link="knee_left"/>
        <child link="support_lower_left"/>
        <axis xyz="-1 0 0"/>
        <limit lower="${-pi/4}" upper="${pi/4}" velocity="100" effort="100"/> 
        <mimic joint="lower_leg_left_joint" multiplier="1"/> 
    </joint>

    <link name="support_lower_left">
        <visual>
            <geometry>
                <mesh filename="package://watschel_description/meshes/3d_modelle/Left_leg/Low_leg_back.stl" scale="0.01 0.01 0.01"/>
            </geometry>
            <material name="green">
                <color rgba="0.2 1 0.2 1"/>
            </material>
        </visual>
        <inertial>
            <mass value="10"/>
            <inertia ixx="0.4" ixy="0.0" ixz="0.0" iyy="0.4" iyz="0.0" izz="0.2"/>
        </inertial>
    </link>


    <link name="foot_left">
        <visual>
            <geometry>
                <mesh filename="package://watschel_description/meshes/3d_modelle/Left_leg/Foot.stl" scale="0.01 0.01 0.01"/> 
            </geometry>
            <material name="green">
                <color rgba="0.0 1 0.2 1"/>
            </material>
        </visual>
        <collision>
            <geometry>
                <box size="0.4 0.8 0.1"/>
            </geometry>
        </collision>
        <inertial>
            <mass value="11"/>
            <inertia ixx="30.922726715508456" ixy="0.0" ixz="0.0" iyy="11.747663442495953" iyz="0.0" izz="31.94689382554976"/>
        </inertial>
    </link>

    <joint name="foot_right_joint" type="fixed">
        <origin xyz="0 0.05 -0.65"/>
        <parent link="leg_lower_right"/>
        <child link="foot_right"/>
        <axis xyz="-1 0 0"/>
        <mimic  joint="lower_leg_right_joint" multiplier="-1" />

    </joint>

    <link name="foot_right">
        <visual>
            <geometry>
                <mesh filename="package://watschel_description/meshes/3d_modelle/Right_leg/Foot.stl" scale="0.01 0.01 0.01"/> 
            </geometry>
            <material name="green">
                <color rgba="0.0 1 0.2 1"/>
            </material>
        </visual>
        <collision>
            <geometry>
                <box size="0.4 0.8 0.1"/>
            </geometry>
            
        </collision>
        <inertial>
            <mass value="11"/>
            <inertia ixx="30.922726715508456" ixy="0.0" ixz="0.0" iyy="11.747663442495953" iyz="0.0" izz="31.94689382554976"/>
        </inertial>
    </link>


    <!--xacro:include filename="example_gazebo.xacro" /-->
    <xacro:include filename="watschel_ros2_control.urdf.xacro"/>

</robot>
